Existing models removed. Here's what local looks like:
1rVWN7z05CHkIwbOJ5Cy3E0seWSpU6SeT
SERAC
datasets
hub
models--meta-llama--Llama-2-7b-hf
modules
wikipedia
Dirs created:
hug
downloading
downloading locuslab/tofu_ft_llama2-7b
Traceback (most recent call last):
  File "/home/gridsan/shossain/.conda/envs/easy/lib/python3.9/site-packages/urllib3/connection.py", line 199, in _new_conn
    sock = connection.create_connection(
  File "/home/gridsan/shossain/.conda/envs/easy/lib/python3.9/site-packages/urllib3/util/connection.py", line 85, in create_connection
    raise err
  File "/home/gridsan/shossain/.conda/envs/easy/lib/python3.9/site-packages/urllib3/util/connection.py", line 73, in create_connection
    sock.connect(sa)
OSError: [Errno 101] Network is unreachable

The above exception was the direct cause of the following exception:

Traceback (most recent call last):
  File "/home/gridsan/shossain/.conda/envs/easy/lib/python3.9/site-packages/urllib3/connectionpool.py", line 789, in urlopen
    response = self._make_request(
  File "/home/gridsan/shossain/.conda/envs/easy/lib/python3.9/site-packages/urllib3/connectionpool.py", line 490, in _make_request
    raise new_e
  File "/home/gridsan/shossain/.conda/envs/easy/lib/python3.9/site-packages/urllib3/connectionpool.py", line 466, in _make_request
    self._validate_conn(conn)
  File "/home/gridsan/shossain/.conda/envs/easy/lib/python3.9/site-packages/urllib3/connectionpool.py", line 1095, in _validate_conn
    conn.connect()
  File "/home/gridsan/shossain/.conda/envs/easy/lib/python3.9/site-packages/urllib3/connection.py", line 693, in connect
    self.sock = sock = self._new_conn()
  File "/home/gridsan/shossain/.conda/envs/easy/lib/python3.9/site-packages/urllib3/connection.py", line 214, in _new_conn
    raise NewConnectionError(
urllib3.exceptions.NewConnectionError: <urllib3.connection.HTTPSConnection object at 0x7fe589978a90>: Failed to establish a new connection: [Errno 101] Network is unreachable

The above exception was the direct cause of the following exception:

Traceback (most recent call last):
  File "/home/gridsan/shossain/.local/lib/python3.9/site-packages/requests/adapters.py", line 667, in send
    resp = conn.urlopen(
  File "/home/gridsan/shossain/.conda/envs/easy/lib/python3.9/site-packages/urllib3/connectionpool.py", line 843, in urlopen
    retries = retries.increment(
  File "/home/gridsan/shossain/.conda/envs/easy/lib/python3.9/site-packages/urllib3/util/retry.py", line 519, in increment
    raise MaxRetryError(_pool, url, reason) from reason  # type: ignore[arg-type]
urllib3.exceptions.MaxRetryError: HTTPSConnectionPool(host='huggingface.co', port=443): Max retries exceeded with url: /api/models/locuslab/tofu_ft_llama2-7b/revision/main (Caused by NewConnectionError('<urllib3.connection.HTTPSConnection object at 0x7fe589978a90>: Failed to establish a new connection: [Errno 101] Network is unreachable'))

During handling of the above exception, another exception occurred:

Traceback (most recent call last):
  File "/home/gridsan/shossain/.local/lib/python3.9/site-packages/huggingface_hub/_snapshot_download.py", line 155, in snapshot_download
    repo_info = api.repo_info(repo_id=repo_id, repo_type=repo_type, revision=revision, token=token)
  File "/home/gridsan/shossain/.local/lib/python3.9/site-packages/huggingface_hub/utils/_validators.py", line 114, in _inner_fn
    return fn(*args, **kwargs)
  File "/home/gridsan/shossain/.local/lib/python3.9/site-packages/huggingface_hub/hf_api.py", line 2756, in repo_info
    return method(
  File "/home/gridsan/shossain/.local/lib/python3.9/site-packages/huggingface_hub/utils/_validators.py", line 114, in _inner_fn
    return fn(*args, **kwargs)
  File "/home/gridsan/shossain/.local/lib/python3.9/site-packages/huggingface_hub/hf_api.py", line 2540, in model_info
    r = get_session().get(path, headers=headers, timeout=timeout, params=params)
  File "/home/gridsan/shossain/.local/lib/python3.9/site-packages/requests/sessions.py", line 602, in get
    return self.request("GET", url, **kwargs)
  File "/home/gridsan/shossain/.local/lib/python3.9/site-packages/requests/sessions.py", line 589, in request
    resp = self.send(prep, **send_kwargs)
  File "/home/gridsan/shossain/.local/lib/python3.9/site-packages/requests/sessions.py", line 703, in send
    r = adapter.send(request, **kwargs)
  File "/home/gridsan/shossain/.local/lib/python3.9/site-packages/huggingface_hub/utils/_http.py", line 93, in send
    return super().send(request, *args, **kwargs)
  File "/home/gridsan/shossain/.local/lib/python3.9/site-packages/requests/adapters.py", line 700, in send
    raise ConnectionError(e, request=request)
requests.exceptions.ConnectionError: (MaxRetryError("HTTPSConnectionPool(host='huggingface.co', port=443): Max retries exceeded with url: /api/models/locuslab/tofu_ft_llama2-7b/revision/main (Caused by NewConnectionError('<urllib3.connection.HTTPSConnection object at 0x7fe589978a90>: Failed to establish a new connection: [Errno 101] Network is unreachable'))"), '(Request ID: 999f390a-4c6b-4f21-a4ee-1b9d88c1e49f)')

The above exception was the direct cause of the following exception:

Traceback (most recent call last):
  File "/home/gridsan/shossain/EasyEdit/download.py", line 18, in <module>
    snapshot_dir = snapshot_download(repo_id=model_name, cache_dir=cache_dir)
  File "/home/gridsan/shossain/.local/lib/python3.9/site-packages/huggingface_hub/utils/_validators.py", line 114, in _inner_fn
    return fn(*args, **kwargs)
  File "/home/gridsan/shossain/.local/lib/python3.9/site-packages/huggingface_hub/_snapshot_download.py", line 235, in snapshot_download
    raise LocalEntryNotFoundError(
huggingface_hub.errors.LocalEntryNotFoundError: An error happened while trying to locate the files on the Hub and we cannot find the appropriate snapshot folder for the specified revision on the local disk. Please check your internet connection and try again.
Model collected. Here is what home looks like:
hub
Model copied. Here is what local looks like:
1rVWN7z05CHkIwbOJ5Cy3E0seWSpU6SeT
SERAC
datasets
hub
models--meta-llama--Llama-2-7b-hf
modules
wikipedia
Home cleared. Here is what home looks like:
2024-12-09 19:41:39,019 - easyeditor.editors.editor - INFO - Instantiating model
12/09/2024 19:41:39 - INFO - easyeditor.editors.editor -   Instantiating model
Traceback (most recent call last):
  File "/home/gridsan/shossain/.conda/envs/easy/lib/python3.9/site-packages/transformers/utils/hub.py", line 402, in cached_file
    resolved_file = hf_hub_download(
  File "/home/gridsan/shossain/.local/lib/python3.9/site-packages/huggingface_hub/utils/_validators.py", line 106, in _inner_fn
    validate_repo_id(arg_value)
  File "/home/gridsan/shossain/.local/lib/python3.9/site-packages/huggingface_hub/utils/_validators.py", line 154, in validate_repo_id
    raise HFValidationError(
huggingface_hub.errors.HFValidationError: Repo id must be in the form 'repo_name' or 'namespace/repo_name': '/home/gridsan/shossain/EasyEdit/scr/models--locuslab--tofu_ft_llama2-7b/snapshots/8fa500e8f345f1dd9cfe95bb4689878c944c9cbd'. Use `repo_type` argument if needed.

The above exception was the direct cause of the following exception:

Traceback (most recent call last):
  File "/home/gridsan/shossain/EasyEdit/run_tofu.py", line 56, in <module>
    editor = BaseEditor.from_hparams(hparams)
  File "/home/gridsan/shossain/EasyEdit/easyeditor/editors/editor.py", line 55, in from_hparams
    return cls(hparams)
  File "/home/gridsan/shossain/EasyEdit/easyeditor/editors/editor.py", line 104, in __init__
    self.model = AutoModelForCausalLM.from_pretrained(self.model_name, **model_kwargs)
  File "/home/gridsan/shossain/.conda/envs/easy/lib/python3.9/site-packages/transformers/models/auto/auto_factory.py", line 485, in from_pretrained
    resolved_config_file = cached_file(
  File "/home/gridsan/shossain/.conda/envs/easy/lib/python3.9/site-packages/transformers/utils/hub.py", line 466, in cached_file
    raise EnvironmentError(
OSError: Incorrect path_or_model_id: '/home/gridsan/shossain/EasyEdit/scr/models--locuslab--tofu_ft_llama2-7b/snapshots/8fa500e8f345f1dd9cfe95bb4689878c944c9cbd'. Please provide either the path to a local folder or the repo_id of a model on the Hub.
