2024-12-14 14:47:14,547 - easyeditor.editors.editor - INFO - Instantiating model
12/14/2024 14:47:14 - INFO - easyeditor.editors.editor -   Instantiating model
Traceback (most recent call last):
  File "/home/gridsan/shossain/.conda/envs/easy/lib/python3.9/site-packages/transformers/utils/hub.py", line 402, in cached_file
    resolved_file = hf_hub_download(
  File "/home/gridsan/shossain/.local/lib/python3.9/site-packages/huggingface_hub/utils/_validators.py", line 106, in _inner_fn
    validate_repo_id(arg_value)
  File "/home/gridsan/shossain/.local/lib/python3.9/site-packages/huggingface_hub/utils/_validators.py", line 154, in validate_repo_id
    raise HFValidationError(
huggingface_hub.errors.HFValidationError: Repo id must be in the form 'repo_name' or 'namespace/repo_name': './hugging_cache/llama-2-7b'. Use `repo_type` argument if needed.

The above exception was the direct cause of the following exception:

Traceback (most recent call last):
  File "/home/gridsan/shossain/EasyEdit/examples/run_zsre_llama2.py", line 54, in <module>
    editor = BaseEditor.from_hparams(hparams)
  File "/home/gridsan/shossain/EasyEdit/examples/../easyeditor/editors/editor.py", line 55, in from_hparams
    return cls(hparams)
  File "/home/gridsan/shossain/EasyEdit/examples/../easyeditor/editors/editor.py", line 104, in __init__
    self.model = AutoModelForCausalLM.from_pretrained(self.model_name, **model_kwargs)
  File "/home/gridsan/shossain/.conda/envs/easy/lib/python3.9/site-packages/transformers/models/auto/auto_factory.py", line 485, in from_pretrained
    resolved_config_file = cached_file(
  File "/home/gridsan/shossain/.conda/envs/easy/lib/python3.9/site-packages/transformers/utils/hub.py", line 466, in cached_file
    raise EnvironmentError(
OSError: Incorrect path_or_model_id: './hugging_cache/llama-2-7b'. Please provide either the path to a local folder or the repo_id of a model on the Hub.
